Workbook
Name Button_429: "LeaseCalc_Lease_Data_List"
Name CellAbove: INDIRECT(ADDRESS(ROW()-1,COLUMN()))
Name CIT: #N/A
Name IQ_CH: 110000
Name IQ_CQ: 5000
Name IQ_CY: 10000
Name IQ_DAILY: 500000
Name IQ_FH: 100000
Name IQ_FQ: 500
Name IQ_FY: 1000
Name IQ_LTM: 2000
Name IQ_MONTH: 15000
Name IQ_NTM: 6000
Name IQ_WEEK: 50000
Name IQ_YTD: 3000
Name TM1REBUILDOPTION: 1

Sheet Control | Setup
A1: Control | Setup
A2: Source: <document_source>
A4: Template Note | B4: Pack A scaffold only: direct formulas/values, no Excel Tables, no required named ranges.
A6: Control | Setup
A7: Field | B7: Value
A8: Engagement / Target
A9: TemplateVersion | B9: v1.0-packA
A10: Currency | B10: USD
A11: Units | B11: $000s
A12: FYEndMonth (1-12) | B12: 12
A13: LatestMonthEnd
A20: Control | Periods
A21: PeriodEndDate | B21: PeriodKey | C21: Label_Flow | D21: Label_Snapshot | E21: FY | F21: IsFYEnd | G21: IsInLast36M | H21: IsTTMEnd | I21: SortOrder
B22: =IF(A22="","",TEXT(A22,"yyyymm")) | C22: =IF(A22="","",TEXT(A22,"mmm-yy")) | D22: =IF(A22="","",TEXT(A22,"mmm-yy")) | E22: =IF(A22="","",YEAR(A22)+(MONTH(A22)>$B$12)) | F22: =IF(A22="","",MONTH(A22)=$B$12) | G22: =IF(OR(A22="",$B$13=""),"",AND(A22<=$B$13,A22>EOMONTH($B$13,-36))) | H22: =IF(OR(A22="",$B$13=""),"",A22=$B$13) | I22: =IF(A22="","",ROW()-21)
B23: =IF(A23="","",TEXT(A23,"yyyymm")) | C23: =IF(A23="","",TEXT(A23,"mmm-yy")) | D23: =IF(A23="","",TEXT(A23,"mmm-yy")) | E23: =IF(A23="","",YEAR(A23)+(MONTH(A23)>$B$12)) | F23: =IF(A23="","",MONTH(A23)=$B$12) | G23: =IF(OR(A23="",$B$13=""),"",AND(A23<=$B$13,A23>EOMONTH($B$13,-36))) | H23: =IF(OR(A23="",$B$13=""),"",A23=$B$13) | I23: =IF(A23="","",ROW()-21)
B24: =IF(A24="","",TEXT(A24,"yyyymm")) | C24: =IF(A24="","",TEXT(A24,"mmm-yy")) | D24: =IF(A24="","",TEXT(A24,"mmm-yy")) | E24: =IF(A24="","",YEAR(A24)+(MONTH(A24)>$B$12)) | F24: =IF(A24="","",MONTH(A24)=$B$12) | G24: =IF(OR(A24="",$B$13=""),"",AND(A24<=$B$13,A24>EOMONTH($B$13,-36))) | H24: =IF(OR(A24="",$B$13=""),"",A24=$B$13) | I24: =IF(A24="","",ROW()-21)
B25: =IF(A25="","",TEXT(A25,"yyyymm")) | C25: =IF(A25="","",TEXT(A25,"mmm-yy")) | D25: =IF(A25="","",TEXT(A25,"mmm-yy")) | E25: =IF(A25="","",YEAR(A25)+(MONTH(A25)>$B$12)) | F25: =IF(A25="","",MONTH(A25)=$B$12) | G25: =IF(OR(A25="",$B$13=""),"",AND(A25<=$B$13,A25>EOMONTH($B$13,-36))) | H25: =IF(OR(A25="",$B$13=""),"",A25=$B$13) | I25: =IF(A25="","",ROW()-21)
B26: =IF(A26="","",TEXT(A26,"yyyymm")) | C26: =IF(A26="","",TEXT(A26,"mmm-yy")) | D26: =IF(A26="","",TEXT(A26,"mmm-yy")) | E26: =IF(A26="","",YEAR(A26)+(MONTH(A26)>$B$12)) | F26: =IF(A26="","",MONTH(A26)=$B$12) | G26: =IF(OR(A26="",$B$13=""),"",AND(A26<=$B$13,A26>EOMONTH($B$13,-36))) | H26: =IF(OR(A26="",$B$13=""),"",A26=$B$13) | I26: =IF(A26="","",ROW()-21)
B27: =IF(A27="","",TEXT(A27,"yyyymm")) | C27: =IF(A27="","",TEXT(A27,"mmm-yy")) | D27: =IF(A27="","",TEXT(A27,"mmm-yy")) | E27: =IF(A27="","",YEAR(A27)+(MONTH(A27)>$B$12)) | F27: =IF(A27="","",MONTH(A27)=$B$12) | G27: =IF(OR(A27="",$B$13=""),"",AND(A27<=$B$13,A27>EOMONTH($B$13,-36))) | H27: =IF(OR(A27="",$B$13=""),"",A27=$B$13) | I27: =IF(A27="","",ROW()-21)
B28: =IF(A28="","",TEXT(A28,"yyyymm")) | C28: =IF(A28="","",TEXT(A28,"mmm-yy")) | D28: =IF(A28="","",TEXT(A28,"mmm-yy")) | E28: =IF(A28="","",YEAR(A28)+(MONTH(A28)>$B$12)) | F28: =IF(A28="","",MONTH(A28)=$B$12) | G28: =IF(OR(A28="",$B$13=""),"",AND(A28<=$B$13,A28>EOMONTH($B$13,-36))) | H28: =IF(OR(A28="",$B$13=""),"",A28=$B$13) | I28: =IF(A28="","",ROW()-21)
B29: =IF(A29="","",TEXT(A29,"yyyymm")) | C29: =IF(A29="","",TEXT(A29,"mmm-yy")) | D29: =IF(A29="","",TEXT(A29,"mmm-yy")) | E29: =IF(A29="","",YEAR(A29)+(MONTH(A29)>$B$12)) | F29: =IF(A29="","",MONTH(A29)=$B$12) | G29: =IF(OR(A29="",$B$13=""),"",AND(A29<=$B$13,A29>EOMONTH($B$13,-36))) | H29: =IF(OR(A29="",$B$13=""),"",A29=$B$13) | I29: =IF(A29="","",ROW()-21)
B30: =IF(A30="","",TEXT(A30,"yyyymm")) | C30: =IF(A30="","",TEXT(A30,"mmm-yy")) | D30: =IF(A30="","",TEXT(A30,"mmm-yy")) | E30: =IF(A30="","",YEAR(A30)+(MONTH(A30)>$B$12)) | F30: =IF(A30="","",MONTH(A30)=$B$12) | G30: =IF(OR(A30="",$B$13=""),"",AND(A30<=$B$13,A30>EOMONTH($B$13,-36))) | H30: =IF(OR(A30="",$B$13=""),"",A30=$B$13) | I30: =IF(A30="","",ROW()-21)
B31: =IF(A31="","",TEXT(A31,"yyyymm")) | C31: =IF(A31="","",TEXT(A31,"mmm-yy")) | D31: =IF(A31="","",TEXT(A31,"mmm-yy")) | E31: =IF(A31="","",YEAR(A31)+(MONTH(A31)>$B$12)) | F31: =IF(A31="","",MONTH(A31)=$B$12) | G31: =IF(OR(A31="",$B$13=""),"",AND(A31<=$B$13,A31>EOMONTH($B$13,-36))) | H31: =IF(OR(A31="",$B$13=""),"",A31=$B$13) | I31: =IF(A31="","",ROW()-21)
B32: =IF(A32="","",TEXT(A32,"yyyymm")) | C32: =IF(A32="","",TEXT(A32,"mmm-yy")) | D32: =IF(A32="","",TEXT(A32,"mmm-yy")) | E32: =IF(A32="","",YEAR(A32)+(MONTH(A32)>$B$12)) | F32: =IF(A32="","",MONTH(A32)=$B$12) | G32: =IF(OR(A32="",$B$13=""),"",AND(A32<=$B$13,A32>EOMONTH($B$13,-36))) | H32: =IF(OR(A32="",$B$13=""),"",A32=$B$13) | I32: =IF(A32="","",ROW()-21)
B33: =IF(A33="","",TEXT(A33,"yyyymm")) | C33: =IF(A33="","",TEXT(A33,"mmm-yy")) | D33: =IF(A33="","",TEXT(A33,"mmm-yy")) | E33: =IF(A33="","",YEAR(A33)+(MONTH(A33)>$B$12)) | F33: =IF(A33="","",MONTH(A33)=$B$12) | G33: =IF(OR(A33="",$B$13=""),"",AND(A33<=$B$13,A33>EOMONTH($B$13,-36))) | H33: =IF(OR(A33="",$B$13=""),"",A33=$B$13) | I33: =IF(A33="","",ROW()-21)
... B69: =IF(A69="","",TEXT(A69,"yyyymm")) | C69: =IF(A69="","",TEXT(A69,"mmm-yy")) | D69: =IF(A69="","",TEXT(A69,"mmm-yy")) | E69: =IF(A69="","",YEAR(A69)+(MONTH(A69)>$B$12)) | F69: =IF(A69="","",MONTH(A69)=$B$12) | G69: =IF(OR(A69="",$B$13=""),"",AND(A69<=$B$13,A69>EOMONTH($B$13,-36))) | H69: =IF(OR(A69="",$B$13=""),"",A69=$B$13) | I69: =IF(A69="","",ROW()-21)

Sheet Control | QC
A1: Control | QC
A2: Source: <document_source>
A4: Workbook QC Status | B4: =IF(COUNTIF(G9:G200,FALSE)>0,"FAIL",IF(COUNTIF(G9:G200,TRUE)>0,"PASS","PENDING"))
A6: Centralized pass/fail matrix linked to check cells across all core sheets.
A7: QC Matrix
A8: CheckID | B8: CheckName | C8: Sheet | D8: CellRef | E8: Expected | F8: Actual | G8: PassFlag | H8: Severity | I8: Notes
A9: QC_IS_NI | B9: Combined IS net income tie-out | C9: Combined | IS | D9: 'Combined | IS'!G28:K28 | E9: 0 | F9: =IF(D9="","",SUMPRODUCT(ABS(INDIRECT(D9)))) | G9: =IF(F9="","",IF(ABS(F9-E9)<=0.01,TRUE,FALSE)) | H9: High | I9: Should resolve to 0
A10: QC_IS_EBITDA | B10: Combined IS EBITDA tie-out | C10: Combined | IS | D10: 'Combined | IS'!G29:K29 | E10: 0 | F10: =IF(D10="","",SUMPRODUCT(ABS(INDIRECT(D10)))) | G10: =IF(F10="","",IF(ABS(F10-E10)<=0.01,TRUE,FALSE)) | H10: High | I10: Should resolve to 0
A11: QC_BS_BAL | B11: Combined BS balance check | C11: Combined | BS | D11: 'Combined | BS'!G28:K28 | E11: 0 | F11: =IF(D11="","",SUMPRODUCT(ABS(INDIRECT(D11)))) | G11: =IF(F11="","",IF(ABS(F11-E11)<=0.01,TRUE,FALSE)) | H11: High | I11: Should resolve to 0
A12: QC_CF_NET | B12: Combined CF net cash tie-out | C12: Combined | CF | D12: 'Combined | CF'!G28:K28 | E12: 0 | F12: =IF(D12="","",SUMPRODUCT(ABS(INDIRECT(D12)))) | G12: =IF(F12="","",IF(ABS(F12-E12)<=0.01,TRUE,FALSE)) | H12: High | I12: Should resolve to 0
A13: QC_QOFE_REV | B13: QofE Summary revenue tie-out | C13: QofE | Summary | D13: 'QofE | Summary'!G20:J20 | E13: 0 | F13: =IF(D13="","",SUMPRODUCT(ABS(INDIRECT(D13)))) | G13: =IF(F13="","",IF(ABS(F13-E13)<=0.01,TRUE,FALSE)) | H13: Med | I13: Should resolve to 0 once linked
A14: QC_QOFE_EB | B14: QofE Summary EBITDA tie-out | C14: QofE | Summary | D14: 'QofE | Summary'!G21:J21 | E14: 0 | F14: =IF(D14="","",SUMPRODUCT(ABS(INDIRECT(D14)))) | G14: =IF(F14="","",IF(ABS(F14-E14)<=0.01,TRUE,FALSE)) | H14: Med | I14: Should resolve to 0 once linked
A15: QC_QOFE_DET | B15: QofE Detail adjusted EBITDA tie-out | C15: QofE | Detail | D15: 'QofE | Detail'!G28:K28 | E15: 0 | F15: =IF(D15="","",SUMPRODUCT(ABS(INDIRECT(D15)))) | G15: =IF(F15="","",IF(ABS(F15-E15)<=0.01,TRUE,FALSE)) | H15: Med | I15: Should resolve to 0 once linked
A16: QC_NWC_SUM | B16: NWC Summary tie-out | C16: NWC | Summary | D16: 'NWC | Summary'!G17:K17 | E16: 0 | F16: =IF(D16="","",SUMPRODUCT(ABS(INDIRECT(D16)))) | G16: =IF(F16="","",IF(ABS(F16-E16)<=0.01,TRUE,FALSE)) | H16: High | I16: Should resolve to 0 once linked
A17: QC_NWC_DET | B17: NWC Detail tie-out | C17: NWC | Detail | D17: 'NWC | Detail'!G28:K28 | E17: 0 | F17: =IF(D17="","",SUMPRODUCT(ABS(INDIRECT(D17)))) | G17: =IF(F17="","",IF(ABS(F17-E17)<=0.01,TRUE,FALSE)) | H17: High | I17: Should resolve to 0 once linked
A18: QC_STRAT_BS | B18: Stratified BS tie-out | C18: Stratified | BS | D18: 'Stratified | BS'!G28:K28 | E18: 0 | F18: =IF(D18="","",SUMPRODUCT(ABS(INDIRECT(D18)))) | G18: =IF(F18="","",IF(ABS(F18-E18)<=0.01,TRUE,FALSE)) | H18: High | I18: Should resolve to 0 once linked
A19: QC_NETDEBT | B19: Net debt tie-out | C19: Net_debt | D19: 'Net_debt'!G28:K28 | E19: 0 | F19: =IF(D19="","",SUMPRODUCT(ABS(INDIRECT(D19)))) | G19: =IF(F19="","",IF(ABS(F19-E19)<=0.01,TRUE,FALSE)) | H19: High | I19: Should resolve to 0 once linked
A20: QC_RECONS_IS | B20: Recons IS section checks | C20: Recons | D20: 'Recons'!H9:H13 | E20: 0 | F20: =IF(D20="","",SUMPRODUCT(ABS(INDIRECT(D20)))) | G20: =IF(F20="","",IF(ABS(F20-E20)<=0.01,TRUE,FALSE)) | H20: Med | I20: Should resolve to 0 once linked
... A26: QC_AGING_ALL | B26: Combined aging tie-out check | C26: Agings | D26: 'Agings'!J40 | E26: 0 | F26: =IF(D26="","",SUMPRODUCT(ABS(INDIRECT(D26)))) | G26: =IF(F26="","",IF(ABS(F26-E26)<=0.01,TRUE,FALSE)) | H26: High | I26: Should resolve to 0 once linked

Sheet Template | Index
A1: Template | Index
A2: Source: <document_source>
A3: Manifest Block
A4: ModuleKey | B4: ModuleName | C4: SheetNames | D4: Purpose | E4: PrimaryInputs | F4: Dependencies | G4: TypicalUseCases | H4: CanInstantiateMultiple
A5: CORE_CONTROLS | B5: Controls | C5: Control | Setup; Control | QC | D5: Template controls and QC center | E5: Manual setup | F5: None | G5: All deals | H5: FALSE
A6: CORE_DATA | B6: Data intake | C6: Data | TB; Data | AR Aging; Data | AP Aging | D6: Standardized data ingestion blocks | E6: Client exports | F6: Control | Setup | G6: All deals | H6: FALSE
A7: CORE_MAPPING | B7: Mappings | C7: Map | COA to Lines; Map | NWC & NetDebt Class; Map | Entities | D7: Account and classification mappings | E7: TB + team mapping decisions | F7: Data | TB | G7: All deals | H7: FALSE
A8: CORE_FINANCIALS | B8: Financial statements | C8: Financials>>; Combined | IS; Combined | BS; Combined | CF; Entity 1 | IS; Entity 1 | BS; Entity 1 | CF | D8: Core financial statement scaffolds for combined and placeholder entity views | E8: Control | Setup; Data | TB; Map | COA to Lines | F8: Pack A tabs | G8: All deals | H8: TRUE
A9: CORE_QOFE | B9: QofE | C9: QofE>>; QofE | Summary; QofE | Detail | D9: QofE scaffold outputs | E9: Control | Setup; Data | TB; Map | COA to Lines | F9: Pack A | G9: All deals | H9: FALSE
A10: CORE_NWC | B10: NWC | C10: NWC>>; NWC | Summary; NWC | Detail; NWC | Days; Stratified | BS | D10: NWC and stratification scaffolds | E10: Control | Setup; Data | TB; Map | NWC & NetDebt Class | F10: Pack A | G10: All deals | H10: FALSE
A11: CORE_NETDEBT | B11: Net debt | C11: Net_debt | D11: Net debt scaffold output | E11: Map | NWC & NetDebt Class; Stratified | BS | F11: CORE_NWC | G11: All deals | H11: FALSE
A12: CORE_RECONS | B12: Reconciliations | C12: Recons | D12: Cross-tab reconciliation mini-grids | E12: Core output checks | F12: Combined | IS; Combined | BS; Combined | CF | G12: All deals | H12: FALSE
A13: CORE_AGINGS | B13: Agings | C13: Agings | D13: AR/AP aging blocks with canonical buckets and tie-outs | E13: Data | AR Aging; Data | AP Aging | F13: Combined | BS | G13: All deals | H13: FALSE
A14: CORE_QC | B14: QC dashboard | C14: Control | QC | D14: Centralized workbook check status | E14: Check cells across core sheets | F14: All core modules | G14: All deals | H14: FALSE
A24: Index Block
A26: Template | Index
A27: Deterministic block coordinate index (fixed anchors, no named ranges required).
A29: Template Note | B29: Pack A scaffold only: direct formulas/values, no Excel Tables, no required named ranges.
A32: Template | Index
A33: SheetName | B33: BlockKey | C33: TopLeftCell | D33: HeaderRowNumber | E33: FirstDataRowNumber | F33: PeriodStartColumn | G33: PeriodHeaderRowNumber | H33: NotesPanelTopLeftCell | I33: OutputType | J33: RefreshRequired | K33: ValidationRule
A34: Control | Setup | B34: CONTROL_SETUP_FIELDS | C34: A7 | D34: 7 | E34: 8 | I34: grid | J34: FALSE | K34: FYEndMonth in B12; LatestMonthEnd in B13
A35: Control | Setup | B35: PERIODS_BLOCK | C35: A20 | D35: 20 | E35: 22 | F35: A | G35: 21 | I35: grid | J35: FALSE | K35: A22:A299 must be month-end dates
A36: Template | Index | B36: MANIFEST_MAIN | C36: A3 | D36: 4 | E36: 5 | I36: grid | J36: FALSE | K36: Module keys should be stable
A37: Template | Index | B37: INDEX_MAIN | C37: A32 | D37: 33 | E37: 34 | I37: grid | J37: FALSE | K37: Update when block anchors move
A38: Data | TB | B38: TB_WIDE_INPUT | C38: A8 | D38: 8 | E38: 9 | F38: G | G38: 8 | I38: grid | J38: FALSE | K38: Month columns map to Control | Setup A22:A57
A39: Data | AR Aging | B39: AR_AGING_INPUT | C39: A8 | D39: 8 | E39: 9 | I39: grid | J39: FALSE | K39: Total column should equal bucket sum
A40: Data | AP Aging | B40: AP_AGING_INPUT | C40: A8 | D40: 8 | E40: 9 | I40: grid | J40: FALSE | K40: Total column should equal bucket sum
A41: Map | COA to Lines | B41: COA_MAP_INPUT | C41: A8 | D41: 8 | E41: 9 | I41: grid | J41: FALSE | K41: LineKey values must be stable
A42: Map | NWC & NetDebt Class | B42: CLASS_MAP_INPUT | C42: A8 | D42: 8 | E42: 9 | I42: grid | J42: FALSE | K42: ClassKey values must be stable
A43: Map | Entities | B43: ENTITIES_MAP_INPUT | C43: A8 | D43: 8 | E43: 9 | I43: grid | J43: FALSE | K43: SortOrder should be sequential
A44: Financials>> | B44: FINANCIALS_DIVIDER | C44: A1 | D44: 1 | E44: 4 | I44: grid | J44: FALSE | K44: Navigation links should point to Pack B sheets
A45: Combined | IS | B45: IS_MAIN | C45: A8 | D45: 8 | E45: 9 | F45: G | G45: 8 | I45: grid | J45: FALSE | K45: Header row uses B8="$'000" (units). Parse FS columns by fixed positions, not header text.
A46: Combined | IS | B46: IS_CHECKS | C46: A27 | D46: 8 | E46: 9 | F46: G | G46: 8 | I46: grid | J46: FALSE | K46: Check values should resolve to 0
A47: Combined | BS | B47: BS_MAIN | C47: A8 | D47: 8 | E47: 9 | F47: G | G47: 8 | I47: grid | J47: FALSE | K47: Header row uses B8="$'000" (units). Parse FS columns by fixed positions, not header text.
A48: Combined | BS | B48: BS_CHECKS | C48: A27 | D48: 8 | E48: 9 | F48: G | G48: 8 | I48: grid | J48: FALSE | K48: Balance check should resolve to 0
A49: Combined | CF | B49: CF_MAIN | C49: A8 | D49: 8 | E49: 9 | F49: G | G49: 8 | I49: grid | J49: FALSE | K49: Header row uses B8="$'000" (units). Parse FS columns by fixed positions, not header text.
A50: Combined | CF | B50: CF_CHECKS | C50: A27 | D50: 8 | E50: 9 | F50: G | G50: 8 | I50: grid | J50: FALSE | K50: Check values should resolve to 0
A51: Entity 1 | IS | B51: ENTITY1_IS_MAIN | C51: A8 | D51: 8 | E51: 9 | F51: G | G51: 8 | I51: grid | J51: FALSE | K51: Header row uses B8="$'000" (units). Parse FS columns by fixed positions, not header text.
A52: Entity 1 | BS | B52: ENTITY1_BS_MAIN | C52: A8 | D52: 8 | E52: 9 | F52: G | G52: 8 | I52: grid | J52: FALSE | K52: Header row uses B8="$'000" (units). Parse FS columns by fixed positions, not header text.
A53: Entity 1 | CF | B53: ENTITY1_CF_MAIN | C53: A8 | D53: 8 | E53: 9 | F53: G | G53: 8 | I53: grid | J53: FALSE | K53: Header row uses B8="$'000" (units). Parse FS columns by fixed positions, not header text.
...

Sheet Data | TB
A1: Data | TB
A2: Source: <document_source>
A4: Template Note | B4: Pack A scaffold only: direct formulas/values, no Excel Tables, no required named ranges.
A7: Data | TB
A8: Entity | B8: AccountNumber | C8: AccountName | D8: FS_SignConvention | E8: Currency | F8: SourceSystem | G8: ='Control | Setup'!A22 | H8: ='Control | Setup'!A23 | I8: ='Control | Setup'!A24 | J8: ='Control | Setup'!A25 | K8: ='Control | Setup'!A26 | L8: ='Control | Setup'!A27 | M8: ='Control | Setup'!A28 | N8: ='Control | Setup'!A29 | O8: ='Control | Setup'!A30 | P8: ='Control | Setup'!A31 | Q8: ='Control | Setup'!A32 | R8: ='Control | Setup'!A33 | S8: ='Control | Setup'!A34 | T8: ='Control | Setup'!A35 | U8: ='Control | Setup'!A36 | V8: ='Control | Setup'!A37 | W8: ='Control | Setup'!A38 | X8: ='Control | Setup'!A39 | Y8: ='Control | Setup'!A40 | Z8: ='Control | Setup'!A41 | AA8: ='Control | Setup'!A42 | AB8: ='Control | Setup'!A43 | AC8: ='Control | Setup'!A44 | AD8: ='Control | Setup'!A45 | AE8: ='Control | Setup'!A46 | AF8: ='Control | Setup'!A47 | AG8: ='Control | Setup'!A48 | AH8: ='Control | Setup'!A49 | AI8: ='Control | Setup'!A50 | AJ8: ='Control | Setup'!A51 | AK8: ='Control | Setup'!A52 | AL8: ='Control | Setup'!A53 | AM8: ='Control | Setup'!A54 | AN8: ='Control | Setup'!A55 | AO8: ='Control | Setup'!A56 | AP8: ='Control | Setup'!A57 | AQ8: FY-2 | AR8: FY-1 | AS8: TTM

Sheet Data | AR Aging
A1: Data | AR Aging
A2: Source: <document_source>
A4: Template Note | B4: Pack A scaffold only: direct formulas/values, no Excel Tables, no required named ranges.
A7: Data | AR Aging
A8: AsAtDate | B8: Entity | C8: CounterpartyName | D8: CounterpartyID | E8: Current | F8: 1-30 | G8: 31-60 | H8: 61-90 | I8: 91-120 | J8: >120 | K8: Total
K9: =IF(A9="","",SUM(E9:J9))
K10: =IF(A10="","",SUM(E10:J10))
K11: =IF(A11="","",SUM(E11:J11))
K12: =IF(A12="","",SUM(E12:J12))
K13: =IF(A13="","",SUM(E13:J13))
K14: =IF(A14="","",SUM(E14:J14))
K15: =IF(A15="","",SUM(E15:J15))
K16: =IF(A16="","",SUM(E16:J16))
K17: =IF(A17="","",SUM(E17:J17))
K18: =IF(A18="","",SUM(E18:J18))
K19: =IF(A19="","",SUM(E19:J19))
K20: =IF(A20="","",SUM(E20:J20))
... K508: =IF(A508="","",SUM(E508:J508))

Sheet Data | AP Aging
A1: Data | AP Aging
A2: Source: <document_source>
A4: Template Note | B4: Pack A scaffold only: direct formulas/values, no Excel Tables, no required named ranges.
A7: Data | AP Aging
A8: AsAtDate | B8: Entity | C8: CounterpartyName | D8: CounterpartyID | E8: Current | F8: 1-30 | G8: 31-60 | H8: 61-90 | I8: 91-120 | J8: >120 | K8: Total
K9: =IF(A9="","",SUM(E9:J9))
K10: =IF(A10="","",SUM(E10:J10))
K11: =IF(A11="","",SUM(E11:J11))
K12: =IF(A12="","",SUM(E12:J12))
K13: =IF(A13="","",SUM(E13:J13))
K14: =IF(A14="","",SUM(E14:J14))
K15: =IF(A15="","",SUM(E15:J15))
K16: =IF(A16="","",SUM(E16:J16))
K17: =IF(A17="","",SUM(E17:J17))
K18: =IF(A18="","",SUM(E18:J18))
K19: =IF(A19="","",SUM(E19:J19))
K20: =IF(A20="","",SUM(E20:J20))
... K508: =IF(A508="","",SUM(E508:J508))

Sheet Map | COA to Lines
A1: Map | COA to Lines
A2: Source: <document_source>
A4: Template Note | B4: Pack A scaffold only: direct formulas/values, no Excel Tables, no required named ranges.
A7: Map | COA to Lines
A8: AccountNumber | B8: AccountName | C8: Statement | D8: LineKey | E8: LineName | F8: GroupKey | G8: SortOrder | H8: SignMultiplier | I8: Notes

Sheet Map | NWC & NetDebt Class
A1: Map | NWC & NetDebt Class
A2: Source: <document_source>
A4: Template Note | B4: Pack A scaffold only: direct formulas/values, no Excel Tables, no required named ranges.
A7: Map | NWC & NetDebt Class
A8: AccountNumber | B8: ClassType | C8: ClassKey | D8: ClassName | E8: Bucket | F8: WorkingCapitalFlag | G8: NetDebtFlag | H8: SortOrder

Sheet Map | Entities
A1: Map | Entities
A2: Source: <document_source>
A4: Template Note | B4: Pack A scaffold only: direct formulas/values, no Excel Tables, no required named ranges.
A7: Map | Entities
A8: EntityName | B8: EntityCode | C8: IncludeFlag | D8: SortOrder | E8: Notes

Sheet Financials>>
A1: Financials>>
A2: Navigation divider for financial statement scaffolds.
A4: =HYPERLINK("#'Combined | IS'!A1","Go to Combined | IS")
A5: Financials>>
A6: =HYPERLINK("#'Combined | CF'!A1","Go to Combined | CF")
A7: =HYPERLINK("#'Entity 1 | IS'!A1","Go to Entity 1 | IS")
A8: =HYPERLINK("#'Entity 1 | BS'!A1","Go to Entity 1 | BS")
A9: =HYPERLINK("#'Entity 1 | CF'!A1","Go to Entity 1 | CF")

Sheet Combined | IS
A1: Combined IS
A2: Source: <document_source>
A7: Combined IS
A8: LineKey | B8: $'000 | C8: TB Account No. | D8: Sign | E8: Source | F8: Comments | G8: ='Control | Setup'!A22 | H8: ='Control | Setup'!A23 | I8: ='Control | Setup'!A24 | J8: ='Control | Setup'!A25 | K8: ='Control | Setup'!A26 | L8: ='Control | Setup'!A27 | M8: ='Control | Setup'!A28 | N8: ='Control | Setup'!A29 | O8: ='Control | Setup'!A30 | P8: ='Control | Setup'!A31 | Q8: ='Control | Setup'!A32 | R8: ='Control | Setup'!A33 | S8: ='Control | Setup'!A34 | T8: ='Control | Setup'!A35 | U8: ='Control | Setup'!A36 | V8: ='Control | Setup'!A37 | W8: ='Control | Setup'!A38 | X8: ='Control | Setup'!A39 | Y8: ='Control | Setup'!A40 | Z8: ='Control | Setup'!A41 | AA8: ='Control | Setup'!A42 | AB8: ='Control | Setup'!A43 | AC8: ='Control | Setup'!A44 | AD8: ='Control | Setup'!A45 | AE8: ='Control | Setup'!A46 | AF8: ='Control | Setup'!A47 | AG8: ='Control | Setup'!A48 | AH8: ='Control | Setup'!A49 | AI8: ='Control | Setup'!A50 | AJ8: ='Control | Setup'!A51 | AK8: ='Control | Setup'!A52 | AL8: ='Control | Setup'!A53 | AM8: ='Control | Setup'!A54 | AN8: ='Control | Setup'!A55 | AO8: ='Control | Setup'!A56 | AP8: ='Control | Setup'!A57 | AQ8: FY-2 | AR8: FY-1 | AS8: TTM
A9: IS_REV | B9: Revenue | D9: + | E9: TB/Map | AQ9: =IF(COUNT(G9:R9)=0,"",SUM(G9:R9)) | AR9: =IF(COUNT(S9:AD9)=0,"",SUM(S9:AD9)) | AS9: =IF(COUNT(AE9:AP9)=0,"",SUM(AE9:AP9))
A10: IS_COGS | B10: Cost of goods sold | D10: + | E10: TB/Map | AQ10: =IF(COUNT(G10:R10)=0,"",SUM(G10:R10)) | AR10: =IF(COUNT(S10:AD10)=0,"",SUM(S10:AD10)) | AS10: =IF(COUNT(AE10:AP10)=0,"",SUM(AE10:AP10))
A11: IS_GP | B11: Gross profit | D11: + | E11: Formula | F11: Derived | G11: =IF(OR(G9="",G10=""),"",G9+G10) | H11: =IF(OR(H9="",H10=""),"",H9+H10) | I11: =IF(OR(I9="",I10=""),"",I9+I10) | J11: =IF(OR(J9="",J10=""),"",J9+J10) | K11: =IF(OR(K9="",K10=""),"",K9+K10) | L11: =IF(OR(L9="",L10=""),"",L9+L10) | M11: =IF(OR(M9="",M10=""),"",M9+M10) | N11: =IF(OR(N9="",N10=""),"",N9+N10) | ... AP11: =IF(OR(AP9="",AP10=""),"",AP9+AP10) | AQ11: =IF(COUNT(G11:R11)=0,"",SUM(G11:R11)) | AR11: =IF(COUNT(S11:AD11)=0,"",SUM(S11:AD11)) | AS11: =IF(COUNT(AE11:AP11)=0,"",SUM(AE11:AP11))
A12: IS_OPEX | B12: Operating expenses | D12: + | E12: TB/Map | AQ12: =IF(COUNT(G12:R12)=0,"",SUM(G12:R12)) | AR12: =IF(COUNT(S12:AD12)=0,"",SUM(S12:AD12)) | AS12: =IF(COUNT(AE12:AP12)=0,"",SUM(AE12:AP12))
A13: IS_OPINC | B13: Operating income | D13: + | E13: Formula | F13: Derived | G13: =IF(OR(G11="",G12=""),"",G11+G12) | H13: =IF(OR(H11="",H12=""),"",H11+H12) | I13: =IF(OR(I11="",I12=""),"",I11+I12) | J13: =IF(OR(J11="",J12=""),"",J11+J12) | K13: =IF(OR(K11="",K12=""),"",K11+K12) | L13: =IF(OR(L11="",L12=""),"",L11+L12) | M13: =IF(OR(M11="",M12=""),"",M11+M12) | N13: =IF(OR(N11="",N12=""),"",N11+N12) | ... AP13: =IF(OR(AP11="",AP12=""),"",AP11+AP12) | AQ13: =IF(COUNT(G13:R13)=0,"",SUM(G13:R13)) | AR13: =IF(COUNT(S13:AD13)=0,"",SUM(S13:AD13)) | AS13: =IF(COUNT(AE13:AP13)=0,"",SUM(AE13:AP13))
A14: IS_INT | B14: Interest expense | D14: + | E14: TB/Map | AQ14: =IF(COUNT(G14:R14)=0,"",SUM(G14:R14)) | AR14: =IF(COUNT(S14:AD14)=0,"",SUM(S14:AD14)) | AS14: =IF(COUNT(AE14:AP14)=0,"",SUM(AE14:AP14))
A15: IS_TAX | B15: Taxes | D15: + | E15: TB/Map | AQ15: =IF(COUNT(G15:R15)=0,"",SUM(G15:R15)) | AR15: =IF(COUNT(S15:AD15)=0,"",SUM(S15:AD15)) | AS15: =IF(COUNT(AE15:AP15)=0,"",SUM(AE15:AP15))
A16: IS_NI | B16: Net income | D16: + | E16: Formula | F16: Main total | G16: =IF(OR(G13="",G14="",G15=""),"",G13+G14+G15) | H16: =IF(OR(H13="",H14="",H15=""),"",H13+H14+H15) | I16: =IF(OR(I13="",I14="",I15=""),"",I13+I14+I15) | J16: =IF(OR(J13="",J14="",J15=""),"",J13+J14+J15) | K16: =IF(OR(K13="",K14="",K15=""),"",K13+K14+K15) | L16: =IF(OR(L13="",L14="",L15=""),"",L13+L14+L15) | M16: =IF(OR(M13="",M14="",M15=""),"",M13+M14+M15) | N16: =IF(OR(N13="",N14="",N15=""),"",N13+N14+N15) | ... AP16: =IF(OR(AP13="",AP14="",AP15=""),"",AP13+AP14+AP15) | AQ16: =IF(COUNT(G16:R16)=0,"",SUM(G16:R16)) | AR16: =IF(COUNT(S16:AD16)=0,"",SUM(S16:AD16)) | AS16: =IF(COUNT(AE16:AP16)=0,"",SUM(AE16:AP16))
A17: IS_ADD_DA | B17: Add back: Depreciation & amortization | D17: + | E17: TB/Map | AQ17: =IF(COUNT(G17:R17)=0,"",SUM(G17:R17)) | AR17: =IF(COUNT(S17:AD17)=0,"",SUM(S17:AD17)) | AS17: =IF(COUNT(AE17:AP17)=0,"",SUM(AE17:AP17))
A18: IS_ADD_INT | B18: Add back: Interest | D18: + | E18: TB/Map | AQ18: =IF(COUNT(G18:R18)=0,"",SUM(G18:R18)) | AR18: =IF(COUNT(S18:AD18)=0,"",SUM(S18:AD18)) | AS18: =IF(COUNT(AE18:AP18)=0,"",SUM(AE18:AP18))
A19: IS_ADD_TAX | B19: Add back: Taxes | D19: + | E19: TB/Map | AQ19: =IF(COUNT(G19:R19)=0,"",SUM(G19:R19)) | AR19: =IF(COUNT(S19:AD19)=0,"",SUM(S19:AD19)) | AS19: =IF(COUNT(AE19:AP19)=0,"",SUM(AE19:AP19))
A20: IS_EBITDA | B20: EBITDA | D20: + | E20: Formula | F20: Secondary total | G20: =IF(OR(G16="",G17="",G18="",G19=""),"",G16+G17+G18+G19) | H20: =IF(OR(H16="",H17="",H18="",H19=""),"",H16+H17+H18+H19) | I20: =IF(OR(I16="",I17="",I18="",I19=""),"",I16+I17+I18+I19) | J20: =IF(OR(J16="",J17="",J18="",J19=""),"",J16+J17+J18+J19) | K20: =IF(OR(K16="",K17="",K18="",K19=""),"",K16+K17+K18+K19) | L20: =IF(OR(L16="",L17="",L18="",L19=""),"",L16+L17+L18+L19) | M20: =IF(OR(M16="",M17="",M18="",M19=""),"",M16+M17+M18+M19) | N20: =IF(OR(N16="",N17="",N18="",N19=""),"",N16+N17+N18+N19) | ... AP20: =IF(OR(AP16="",AP17="",AP18="",AP19=""),"",AP16+AP17+AP18+AP19) | AQ20: =IF(COUNT(G20:R20)=0,"",SUM(G20:R20)) | AR20: =IF(COUNT(S20:AD20)=0,"",SUM(S20:AD20)) | AS20: =IF(COUNT(AE20:AP20)=0,"",SUM(AE20:AP20))
A27: IS_CHECKS
A28: Net income tie-out | G28: =IF(G16="","",G16-(G13+G14+G15)) | H28: =IF(H16="","",H16-(H13+H14+H15)) | I28: =IF(I16="","",I16-(I13+I14+I15)) | J28: =IF(J16="","",J16-(J13+J14+J15)) | K28: =IF(K16="","",K16-(K13+K14+K15)) | L28: =IF(L16="","",L16-(L13+L14+L15)) | M28: =IF(M16="","",M16-(M13+M14+M15)) | N28: =IF(N16="","",N16-(N13+N14+N15)) | ... AS28: =IF(AS16="","",AS16-(AS13+AS14+AS15))
A29: EBITDA tie-out | G29: =IF(G20="","",G20-(G16+G17+G18+G19)) | H29: =IF(H20="","",H20-(H16+H17+H18+H19)) | I29: =IF(I20="","",I20-(I16+I17+I18+I19)) | J29: =IF(J20="","",J20-(J16+J17+J18+J19)) | K29: =IF(K20="","",K20-(K16+K17+K18+K19)) | L29: =IF(L20="","",L20-(L16+L17+L18+L19)) | M29: =IF(M20="","",M20-(M16+M17+M18+M19)) | N29: =IF(N20="","",N20-(N16+N17+N18+N19)) | ... AS29: =IF(AS20="","",AS20-(AS16+AS17+AS18+AS19))

Sheet Combined | BS
A1: Combined BS
A2: Source: <document_source>
A7: Combined BS
A8: LineKey | B8: $'000 | C8: TB Account No. | D8: Sign | E8: Source | F8: Comments | G8: ='Control | Setup'!A22 | H8: ='Control | Setup'!A23 | I8: ='Control | Setup'!A24 | J8: ='Control | Setup'!A25 | K8: ='Control | Setup'!A26 | L8: ='Control | Setup'!A27 | M8: ='Control | Setup'!A28 | N8: ='Control | Setup'!A29 | O8: ='Control | Setup'!A30 | P8: ='Control | Setup'!A31 | Q8: ='Control | Setup'!A32 | R8: ='Control | Setup'!A33 | S8: ='Control | Setup'!A34 | T8: ='Control | Setup'!A35 | U8: ='Control | Setup'!A36 | V8: ='Control | Setup'!A37 | W8: ='Control | Setup'!A38 | X8: ='Control | Setup'!A39 | Y8: ='Control | Setup'!A40 | Z8: ='Control | Setup'!A41 | AA8: ='Control | Setup'!A42 | AB8: ='Control | Setup'!A43 | AC8: ='Control | Setup'!A44 | AD8: ='Control | Setup'!A45 | AE8: ='Control | Setup'!A46 | AF8: ='Control | Setup'!A47 | AG8: ='Control | Setup'!A48 | AH8: ='Control | Setup'!A49 | AI8: ='Control | Setup'!A50 | AJ8: ='Control | Setup'!A51 | AK8: ='Control | Setup'!A52 | AL8: ='Control | Setup'!A53 | AM8: ='Control | Setup'!A54 | AN8: ='Control | Setup'!A55 | AO8: ='Control | Setup'!A56 | AP8: ='Control | Setup'!A57 | AQ8: FY-2 | AR8: FY-1 | AS8: TTM
A9: BS_CASH | B9: Cash | D9: + | E9: TB/Map | AQ9: =R9 | AR9: =AD9 | AS9: =AP9
A10: BS_AR | B10: Accounts receivable | D10: + | E10: TB/Map | AQ10: =R10 | AR10: =AD10 | AS10: =AP10
A11: BS_INV | B11: Inventory | D11: + | E11: TB/Map | AQ11: =R11 | AR11: =AD11 | AS11: =AP11
A12: BS_OCA | B12: Other current assets | D12: + | E12: TB/Map | AQ12: =R12 | AR12: =AD12 | AS12: =AP12
A13: BS_TCA | B13: Total current assets | D13: + | E13: Formula | F13: Derived | G13: =IF(COUNT(G9:G12)=0,"",SUM(G9:G12)) | H13: =IF(COUNT(H9:H12)=0,"",SUM(H9:H12)) | I13: =IF(COUNT(I9:I12)=0,"",SUM(I9:I12)) | J13: =IF(COUNT(J9:J12)=0,"",SUM(J9:J12)) | K13: =IF(COUNT(K9:K12)=0,"",SUM(K9:K12)) | L13: =IF(COUNT(L9:L12)=0,"",SUM(L9:L12)) | M13: =IF(COUNT(M9:M12)=0,"",SUM(M9:M12)) | N13: =IF(COUNT(N9:N12)=0,"",SUM(N9:N12)) | ... AP13: =IF(COUNT(AP9:AP12)=0,"",SUM(AP9:AP12)) | AQ13: =R13 | AR13: =AD13 | AS13: =AP13
A14: BS_PPE | B14: PP&E | D14: + | E14: TB/Map | AQ14: =R14 | AR14: =AD14 | AS14: =AP14
A15: BS_OTA | B15: Other assets | D15: + | E15: TB/Map | AQ15: =R15 | AR15: =AD15 | AS15: =AP15
A16: BS_TA | B16: Total assets | D16: + | E16: Formula | F16: Main total | G16: =IF(COUNT(G13:G15)=0,"",SUM(G13:G15)) | H16: =IF(COUNT(H13:H15)=0,"",SUM(H13:H15)) | I16: =IF(COUNT(I13:I15)=0,"",SUM(I13:I15)) | J16: =IF(COUNT(J13:J15)=0,"",SUM(J13:J15)) | K16: =IF(COUNT(K13:K15)=0,"",SUM(K13:K15)) | L16: =IF(COUNT(L13:L15)=0,"",SUM(L13:L15)) | M16: =IF(COUNT(M13:M15)=0,"",SUM(M13:M15)) | N16: =IF(COUNT(N13:N15)=0,"",SUM(N13:N15)) | ... AP16: =IF(COUNT(AP13:AP15)=0,"",SUM(AP13:AP15)) | AQ16: =R16 | AR16: =AD16 | AS16: =AP16
A17: BS_AP | B17: Accounts payable | D17: + | E17: TB/Map | AQ17: =R17 | AR17: =AD17 | AS17: =AP17
A18: BS_ACCR | B18: Accrued liabilities | D18: + | E18: TB/Map | AQ18: =R18 | AR18: =AD18 | AS18: =AP18
A19: BS_DEBT | B19: Debt | D19: + | E19: TB/Map | AQ19: =R19 | AR19: =AD19 | AS19: =AP19
A20: BS_OL | B20: Other liabilities | D20: + | E20: TB/Map | AQ20: =R20 | AR20: =AD20 | AS20: =AP20
A21: BS_TL | B21: Total liabilities | D21: + | E21: Formula | F21: Derived | G21: =IF(COUNT(G17:G20)=0,"",SUM(G17:G20)) | H21: =IF(COUNT(H17:H20)=0,"",SUM(H17:H20)) | I21: =IF(COUNT(I17:I20)=0,"",SUM(I17:I20)) | J21: =IF(COUNT(J17:J20)=0,"",SUM(J17:J20)) | K21: =IF(COUNT(K17:K20)=0,"",SUM(K17:K20)) | L21: =IF(COUNT(L17:L20)=0,"",SUM(L17:L20)) | M21: =IF(COUNT(M17:M20)=0,"",SUM(M17:M20)) | N21: =IF(COUNT(N17:N20)=0,"",SUM(N17:N20)) | ... AP21: =IF(COUNT(AP17:AP20)=0,"",SUM(AP17:AP20)) | AQ21: =R21 | AR21: =AD21 | AS21: =AP21
A22: BS_EQ | B22: Equity | D22: + | E22: TB/Map | AQ22: =R22 | AR22: =AD22 | AS22: =AP22
A23: BS_TLE | B23: Total liabilities + equity | D23: + | E23: Formula | F23: Derived | G23: =IF(COUNT(G21:G22)=0,"",SUM(G21:G22)) | H23: =IF(COUNT(H21:H22)=0,"",SUM(H21:H22)) | I23: =IF(COUNT(I21:I22)=0,"",SUM(I21:I22)) | J23: =IF(COUNT(J21:J22)=0,"",SUM(J21:J22)) | K23: =IF(COUNT(K21:K22)=0,"",SUM(K21:K22)) | L23: =IF(COUNT(L21:L22)=0,"",SUM(L21:L22)) | M23: =IF(COUNT(M21:M22)=0,"",SUM(M21:M22)) | N23: =IF(COUNT(N21:N22)=0,"",SUM(N21:N22)) | ... AP23: =IF(COUNT(AP21:AP22)=0,"",SUM(AP21:AP22)) | AQ23: =R23 | AR23: =AD23 | AS23: =AP23
A27: BS_CHECKS
A28: Balance check (Assets - Liabilities & Equity) | G28: =IF(OR(G16="",G23=""),"",G16-G23) | H28: =IF(OR(H16="",H23=""),"",H16-H23) | I28: =IF(OR(I16="",I23=""),"",I16-I23) | J28: =IF(OR(J16="",J23=""),"",J16-J23) | K28: =IF(OR(K16="",K23=""),"",K16-K23) | L28: =IF(OR(L16="",L23=""),"",L16-L23) | M28: =IF(OR(M16="",M23=""),"",M16-M23) | N28: =IF(OR(N16="",N23=""),"",N16-N23) | ... AS28: =IF(OR(AS16="",AS23=""),"",AS16-AS23)

Sheet Combined | CF
A1: Combined CF
A2: Source: <document_source>
A7: Combined CF
A8: LineKey | B8: $'000 | C8: TB Account No. | D8: Sign | E8: Source | F8: Comments | G8: ='Control | Setup'!A22 | H8: ='Control | Setup'!A23 | I8: ='Control | Setup'!A24 | J8: ='Control | Setup'!A25 | K8: ='Control | Setup'!A26 | L8: ='Control | Setup'!A27 | M8: ='Control | Setup'!A28 | N8: ='Control | Setup'!A29 | O8: ='Control | Setup'!A30 | P8: ='Control | Setup'!A31 | Q8: ='Control | Setup'!A32 | R8: ='Control | Setup'!A33 | S8: ='Control | Setup'!A34 | T8: ='Control | Setup'!A35 | U8: ='Control | Setup'!A36 | V8: ='Control | Setup'!A37 | W8: ='Control | Setup'!A38 | X8: ='Control | Setup'!A39 | Y8: ='Control | Setup'!A40 | Z8: ='Control | Setup'!A41 | AA8: ='Control | Setup'!A42 | AB8: ='Control | Setup'!A43 | AC8: ='Control | Setup'!A44 | AD8: ='Control | Setup'!A45 | AE8: ='Control | Setup'!A46 | AF8: ='Control | Setup'!A47 | AG8: ='Control | Setup'!A48 | AH8: ='Control | Setup'!A49 | AI8: ='Control | Setup'!A50 | AJ8: ='Control | Setup'!A51 | AK8: ='Control | Setup'!A52 | AL8: ='Control | Setup'!A53 | AM8: ='Control | Setup'!A54 | AN8: ='Control | Setup'!A55 | AO8: ='Control | Setup'!A56 | AP8: ='Control | Setup'!A57 | AQ8: FY-2 | AR8: FY-1 | AS8: TTM
A9: CF_EBITDA | B9: EBITDA | D9: + | E9: Link/Map | AQ9: =IF(COUNT(G9:R9)=0,"",SUM(G9:R9)) | AR9: =IF(COUNT(S9:AD9)=0,"",SUM(S9:AD9)) | AS9: =IF(COUNT(AE9:AP9)=0,"",SUM(AE9:AP9))
A10: CF_CHG_NWC | B10: Change in NWC | D10: + | E10: Link/Map | AQ10: =IF(COUNT(G10:R10)=0,"",SUM(G10:R10)) | AR10: =IF(COUNT(S10:AD10)=0,"",SUM(S10:AD10)) | AS10: =IF(COUNT(AE10:AP10)=0,"",SUM(AE10:AP10))
A11: CF_CAPEX | B11: Capex | D11: + | E11: Link/Map | AQ11: =IF(COUNT(G11:R11)=0,"",SUM(G11:R11)) | AR11: =IF(COUNT(S11:AD11)=0,"",SUM(S11:AD11)) | AS11: =IF(COUNT(AE11:AP11)=0,"",SUM(AE11:AP11))
A12: CF_OTHER | B12: Other | D12: + | E12: Link/Map | AQ12: =IF(COUNT(G12:R12)=0,"",SUM(G12:R12)) | AR12: =IF(COUNT(S12:AD12)=0,"",SUM(S12:AD12)) | AS12: =IF(COUNT(AE12:AP12)=0,"",SUM(AE12:AP12))
A13: CF_NET | B13: Net cash flow | D13: + | E13: Formula | F13: Derived | G13: =IF(COUNT(G9:G12)=0,"",SUM(G9:G12)) | H13: =IF(COUNT(H9:H12)=0,"",SUM(H9:H12)) | I13: =IF(COUNT(I9:I12)=0,"",SUM(I9:I12)) | J13: =IF(COUNT(J9:J12)=0,"",SUM(J9:J12)) | K13: =IF(COUNT(K9:K12)=0,"",SUM(K9:K12)) | L13: =IF(COUNT(L9:L12)=0,"",SUM(L9:L12)) | M13: =IF(COUNT(M9:M12)=0,"",SUM(M9:M12)) | N13: =IF(COUNT(N9:N12)=0,"",SUM(N9:N12)) | ... AP13: =IF(COUNT(AP9:AP12)=0,"",SUM(AP9:AP12)) | AQ13: =IF(COUNT(G13:R13)=0,"",SUM(G13:R13)) | AR13: =IF(COUNT(S13:AD13)=0,"",SUM(S13:AD13)) | AS13: =IF(COUNT(AE13:AP13)=0,"",SUM(AE13:AP13))
A27: CF_CHECKS
A28: Net cash tie-out | G28: =IF(G13="","",G13-SUM(G9:G12)) | H28: =IF(H13="","",H13-SUM(H9:H12)) | I28: =IF(I13="","",I13-SUM(I9:I12)) | J28: =IF(J13="","",J13-SUM(J9:J12)) | K28: =IF(K13="","",K13-SUM(K9:K12)) | L28: =IF(L13="","",L13-SUM(L9:L12)) | M28: =IF(M13="","",M13-SUM(M9:M12)) | N28: =IF(N13="","",N13-SUM(N9:N12)) | ... AS28: =IF(AS13="","",AS13-SUM(AS9:AS12))

Sheet Entity 1 | IS
A1: Entity 1 IS
A2: Source: <document_source>
A7: Entity 1 IS
A8: LineKey | B8: $'000 | C8: TB Account No. | D8: Sign | E8: Source | F8: Comments | G8: ='Control | Setup'!A22 | H8: ='Control | Setup'!A23 | I8: ='Control | Setup'!A24 | J8: ='Control | Setup'!A25 | K8: ='Control | Setup'!A26 | L8: ='Control | Setup'!A27 | M8: ='Control | Setup'!A28 | N8: ='Control | Setup'!A29 | O8: ='Control | Setup'!A30 | P8: ='Control | Setup'!A31 | Q8: ='Control | Setup'!A32 | R8: ='Control | Setup'!A33 | S8: ='Control | Setup'!A34 | T8: ='Control | Setup'!A35 | U8: ='Control | Setup'!A36 | V8: ='Control | Setup'!A37 | W8: ='Control | Setup'!A38 | X8: ='Control | Setup'!A39 | Y8: ='Control | Setup'!A40 | Z8: ='Control | Setup'!A41 | AA8: ='Control | Setup'!A42 | AB8: ='Control | Setup'!A43 | AC8: ='Control | Setup'!A44 | AD8: ='Control | Setup'!A45 | AE8: ='Control | Setup'!A46 | AF8: ='Control | Setup'!A47 | AG8: ='Control | Setup'!A48 | AH8: ='Control | Setup'!A49 | AI8: ='Control | Setup'!A50 | AJ8: ='Control | Setup'!A51 | AK8: ='Control | Setup'!A52 | AL8: ='Control | Setup'!A53 | AM8: ='Control | Setup'!A54 | AN8: ='Control | Setup'!A55 | AO8: ='Control | Setup'!A56 | AP8: ='Control | Setup'!A57 | AQ8: FY-2 | AR8: FY-1 | AS8: TTM
A9: IS_REV | B9: Revenue | D9: + | E9: TB/Map | AQ9: =IF(COUNT(G9:R9)=0,"",SUM(G9:R9)) | AR9: =IF(COUNT(S9:AD9)=0,"",SUM(S9:AD9)) | AS9: =IF(COUNT(AE9:AP9)=0,"",SUM(AE9:AP9))
A10: IS_COGS | B10: Cost of goods sold | D10: + | E10: TB/Map | AQ10: =IF(COUNT(G10:R10)=0,"",SUM(G10:R10)) | AR10: =IF(COUNT(S10:AD10)=0,"",SUM(S10:AD10)) | AS10: =IF(COUNT(AE10:AP10)=0,"",SUM(AE10:AP10))
A11: IS_GP | B11: Gross profit | D11: + | E11: Formula | F11: Derived | G11: =IF(OR(G9="",G10=""),"",G9+G10) | H11: =IF(OR(H9="",H10=""),"",H9+H10) | I11: =IF(OR(I9="",I10=""),"",I9+I10) | J11: =IF(OR(J9="",J10=""),"",J9+J10) | K11: =IF(OR(K9="",K10=""),"",K9+K10) | L11: =IF(OR(L9="",L10=""),"",L9+L10) | M11: =IF(OR(M9="",M10=""),"",M9+M10) | N11: =IF(OR(N9="",N10=""),"",N9+N10) | ... AP11: =IF(OR(AP9="",AP10=""),"",AP9+AP10) | AQ11: =IF(COUNT(G11:R11)=0,"",SUM(G11:R11)) | AR11: =IF(COUNT(S11:AD11)=0,"",SUM(S11:AD11)) | AS11: =IF(COUNT(AE11:AP11)=0,"",SUM(AE11:AP11))
A12: IS_OPEX | B12: Operating expenses | D12: + | E12: TB/Map | AQ12: =IF(COUNT(G12:R12)=0,"",SUM(G12:R12)) | AR12: =IF(COUNT(S12:AD12)=0,"",SUM(S12:AD12)) | AS12: =IF(COUNT(AE12:AP12)=0,"",SUM(AE12:AP12))
A13: IS_OPINC | B13: Operating income | D13: + | E13: Formula | F13: Derived | G13: =IF(OR(G11="",G12=""),"",G11+G12) | H13: =IF(OR(H11="",H12=""),"",H11+H12) | I13: =IF(OR(I11="",I12=""),"",I11+I12) | J13: =IF(OR(J11="",J12=""),"",J11+J12) | K13: =IF(OR(K11="",K12=""),"",K11+K12) | L13: =IF(OR(L11="",L12=""),"",L11+L12) | M13: =IF(OR(M11="",M12=""),"",M11+M12) | N13: =IF(OR(N11="",N12=""),"",N11+N12) | ... AP13: =IF(OR(AP11="",AP12=""),"",AP11+AP12) | AQ13: =IF(COUNT(G13:R13)=0,"",SUM(G13:R13)) | AR13: =IF(COUNT(S13:AD13)=0,"",SUM(S13:AD13)) | AS13: =IF(COUNT(AE13:AP13)=0,"",SUM(AE13:AP13))
A14: IS_INT | B14: Interest expense | D14: + | E14: TB/Map | AQ14: =IF(COUNT(G14:R14)=0,"",SUM(G14:R14)) | AR14: =IF(COUNT(S14:AD14)=0,"",SUM(S14:AD14)) | AS14: =IF(COUNT(AE14:AP14)=0,"",SUM(AE14:AP14))
A15: IS_TAX | B15: Taxes | D15: + | E15: TB/Map | AQ15: =IF(COUNT(G15:R15)=0,"",SUM(G15:R15)) | AR15: =IF(COUNT(S15:AD15)=0,"",SUM(S15:AD15)) | AS15: =IF(COUNT(AE15:AP15)=0,"",SUM(AE15:AP15))
A16: IS_NI | B16: Net income | D16: + | E16: Formula | F16: Main total | G16: =IF(OR(G13="",G14="",G15=""),"",G13+G14+G15) | H16: =IF(OR(H13="",H14="",H15=""),"",H13+H14+H15) | I16: =IF(OR(I13="",I14="",I15=""),"",I13+I14+I15) | J16: =IF(OR(J13="",J14="",J15=""),"",J13+J14+J15) | K16: =IF(OR(K13="",K14="",K15=""),"",K13+K14+K15) | L16: =IF(OR(L13="",L14="",L15=""),"",L13+L14+L15) | M16: =IF(OR(M13="",M14="",M15=""),"",M13+M14+M15) | N16: =IF(OR(N13="",N14="",N15=""),"",N13+N14+N15) | ... AP16: =IF(OR(AP13="",AP14="",AP15=""),"",AP13+AP14+AP15) | AQ16: =IF(COUNT(G16:R16)=0,"",SUM(G16:R16)) | AR16: =IF(COUNT(S16:AD16)=0,"",SUM(S16:AD16)) | AS16: =IF(COUNT(AE16:AP16)=0,"",SUM(AE16:AP16))
A17: IS_ADD_DA | B17: Add back: Depreciation & amortization | D17: + | E17: TB/Map | AQ17: =IF(COUNT(G17:R17)=0,"",SUM(G17:R17)) | AR17: =IF(COUNT(S17:AD17)=0,"",SUM(S17:AD17)) | AS17: =IF(COUNT(AE17:AP17)=0,"",SUM(AE17:AP17))
A18: IS_ADD_INT | B18: Add back: Interest | D18: + | E18: TB/Map | AQ18: =IF(COUNT(G18:R18)=0,"",SUM(G18:R18)) | AR18: =IF(COUNT(S18:AD18)=0,"",SUM(S18:AD18)) | AS18: =IF(COUNT(AE18:AP18)=0,"",SUM(AE18:AP18))
A19: IS_ADD_TAX | B19: Add back: Taxes | D19: + | E19: TB/Map | AQ19: =IF(COUNT(G19:R19)=0,"",SUM(G19:R19)) | AR19: =IF(COUNT(S19:AD19)=0,"",SUM(S19:AD19)) | AS19: =IF(COUNT(AE19:AP19)=0,"",SUM(AE19:AP19))
A20: IS_EBITDA | B20: EBITDA | D20: + | E20: Formula | F20: Secondary total | G20: =IF(OR(G16="",G17="",G18="",G19=""),"",G16+G17+G18+G19) | H20: =IF(OR(H16="",H17="",H18="",H19=""),"",H16+H17+H18+H19) | I20: =IF(OR(I16="",I17="",I18="",I19=""),"",I16+I17+I18+I19) | J20: =IF(OR(J16="",J17="",J18="",J19=""),"",J16+J17+J18+J19) | K20: =IF(OR(K16="",K17="",K18="",K19=""),"",K16+K17+K18+K19) | L20: =IF(OR(L16="",L17="",L18="",L19=""),"",L16+L17+L18+L19) | M20: =IF(OR(M16="",M17="",M18="",M19=""),"",M16+M17+M18+M19) | N20: =IF(OR(N16="",N17="",N18="",N19=""),"",N16+N17+N18+N19) | ... AP20: =IF(OR(AP16="",AP17="",AP18="",AP19=""),"",AP16+AP17+AP18+AP19) | AQ20: =IF(COUNT(G20:R20)=0,"",SUM(G20:R20)) | AR20: =IF(COUNT(S20:AD20)=0,"",SUM(S20:AD20)) | AS20: =IF(COUNT(AE20:AP20)=0,"",SUM(AE20:AP20))
A27: IS_CHECKS
A28: Net income tie-out | G28: =IF(G16="","",G16-(G13+G14+G15)) | H28: =IF(H16="","",H16-(H13+H14+H15)) | I28: =IF(I16="","",I16-(I13+I14+I15)) | J28: =IF(J16="","",J16-(J13+J14+J15)) | K28: =IF(K16="","",K16-(K13+K14+K15)) | L28: =IF(L16="","",L16-(L13+L14+L15)) | M28: =IF(M16="","",M16-(M13+M14+M15)) | N28: =IF(N16="","",N16-(N13+N14+N15)) | ... AS28: =IF(AS16="","",AS16-(AS13+AS14+AS15))
A29: EBITDA tie-out | G29: =IF(G20="","",G20-(G16+G17+G18+G19)) | H29: =IF(H20="","",H20-(H16+H17+H18+H19)) | I29: =IF(I20="","",I20-(I16+I17+I18+I19)) | J29: =IF(J20="","",J20-(J16+J17+J18+J19)) | K29: =IF(K20="","",K20-(K16+K17+K18+K19)) | L29: =IF(L20="","",L20-(L16+L17+L18+L19)) | M29: =IF(M20="","",M20-(M16+M17+M18+M19)) | N29: =IF(N20="","",N20-(N16+N17+N18+N19)) | ... AS29: =IF(AS20="","",AS20-(AS16+AS17+AS18+AS19))

Sheet Entity 1 | BS
A1: Entity 1 BS
A2: Source: <document_source>
A7: Entity 1 BS
A8: LineKey | B8: $'000 | C8: TB Account No. | D8: Sign | E8: Source | F8: Comments | G8: ='Control | Setup'!A22 | H8: ='Control | Setup'!A23 | I8: ='Control | Setup'!A24 | J8: ='Control | Setup'!A25 | K8: ='Control | Setup'!A26 | L8: ='Control | Setup'!A27 | M8: ='Control | Setup'!A28 | N8: ='Control | Setup'!A29 | O8: ='Control | Setup'!A30 | P8: ='Control | Setup'!A31 | Q8: ='Control | Setup'!A32 | R8: ='Control | Setup'!A33 | S8: ='Control | Setup'!A34 | T8: ='Control | Setup'!A35 | U8: ='Control | Setup'!A36 | V8: ='Control | Setup'!A37 | W8: ='Control | Setup'!A38 | X8: ='Control | Setup'!A39 | Y8: ='Control | Setup'!A40 | Z8: ='Control | Setup'!A41 | AA8: ='Control | Setup'!A42 | AB8: ='Control | Setup'!A43 | AC8: ='Control | Setup'!A44 | AD8: ='Control | Setup'!A45 | AE8: ='Control | Setup'!A46 | AF8: ='Control | Setup'!A47 | AG8: ='Control | Setup'!A48 | AH8: ='Control | Setup'!A49 | AI8: ='Control | Setup'!A50 | AJ8: ='Control | Setup'!A51 | AK8: ='Control | Setup'!A52 | AL8: ='Control | Setup'!A53 | AM8: ='Control | Setup'!A54 | AN8: ='Control | Setup'!A55 | AO8: ='Control | Setup'!A56 | AP8: ='Control | Setup'!A57 | AQ8: FY-2 | AR8: FY-1 | AS8: TTM
A9: BS_CASH | B9: Cash | D9: + | E9: TB/Map | AQ9: =R9 | AR9: =AD9 | AS9: =AP9
A10: BS_AR | B10: Accounts receivable | D10: + | E10: TB/Map | AQ10: =R10 | AR10: =AD10 | AS10: =AP10
A11: BS_INV | B11: Inventory | D11: + | E11: TB/Map | AQ11: =R11 | AR11: =AD11 | AS11: =AP11
A12: BS_OCA | B12: Other current assets | D12: + | E12: TB/Map | AQ12: =R12 | AR12: =AD12 | AS12: =AP12
A13: BS_TCA | B13: Total current assets | D13: + | E13: Formula | F13: Derived | G13: =IF(COUNT(G9:G12)=0,"",SUM(G9:G12)) | H13: =IF(COUNT(H9:H12)=0,"",SUM(H9:H12)) | I13: =IF(COUNT(I9:I12)=0,"",SUM(I9:I12)) | J13: =IF(COUNT(J9:J12)=0,"",SUM(J9:J12)) | K13: =IF(COUNT(K9:K12)=0,"",SUM(K9:K12)) | L13: =IF(COUNT(L9:L12)=0,"",SUM(L9:L12)) | M13: =IF(COUNT(M9:M12)=0,"",SUM(M9:M12)) | N13: =IF(COUNT(N9:N12)=0,"",SUM(N9:N12)) | ... AP13: =IF(COUNT(AP9:AP12)=0,"",SUM(AP9:AP12)) | AQ13: =R13 | AR13: =AD13 | AS13: =AP13
A14: BS_PPE | B14: PP&E | D14: + | E14: TB/Map | AQ14: =R14 | AR14: =AD14 | AS14: =AP14
A15: BS_OTA | B15: Other assets | D15: + | E15: TB/Map | AQ15: =R15 | AR15: =AD15 | AS15: =AP15
A16: BS_TA | B16: Total assets | D16: + | E16: Formula | F16: Main total | G16: =IF(COUNT(G13:G15)=0,"",SUM(G13:G15)) | H16: =IF(COUNT(H13:H15)=0,"",SUM(H13:H15)) | I16: =IF(COUNT(I13:I15)=0,"",SUM(I13:I15)) | J16: =IF(COUNT(J13:J15)=0,"",SUM(J13:J15)) | K16: =IF(COUNT(K13:K15)=0,"",SUM(K13:K15)) | L16: =IF(COUNT(L13:L15)=0,"",SUM(L13:L15)) | M16: =IF(COUNT(M13:M15)=0,"",SUM(M13:M15)) | N16: =IF(COUNT(N13:N15)=0,"",SUM(N13:N15)) | ... AP16: =IF(COUNT(AP13:AP15)=0,"",SUM(AP13:AP15)) | AQ16: =R16 | AR16: =AD16 | AS16: =AP16
A17: BS_AP | B17: Accounts payable | D17: + | E17: TB/Map | AQ17: =R17 | AR17: =AD17 | AS17: =AP17
A18: BS_ACCR | B18: Accrued liabilities | D18: + | E18: TB/Map | AQ18: =R18 | AR18: =AD18 | AS18: =AP18
A19: BS_DEBT | B19: Debt | D19: + | E19: TB/Map | AQ19: =R19 | AR19: =AD19 | AS19: =AP19
A20: BS_OL | B20: Other liabilities | D20: + | E20: TB/Map | AQ20: =R20 | AR20: =AD20 | AS20: =AP20
A21: BS_TL | B21: Total liabilities | D21: + | E21: Formula | F21: Derived | G21: =IF(COUNT(G17:G20)=0,"",SUM(G17:G20)) | H21: =IF(COUNT(H17:H20)=0,"",SUM(H17:H20)) | I21: =IF(COUNT(I17:I20)=0,"",SUM(I17:I20)) | J21: =IF(COUNT(J17:J20)=0,"",SUM(J17:J20)) | K21: =IF(COUNT(K17:K20)=0,"",SUM(K17:K20)) | L21: =IF(COUNT(L17:L20)=0,"",SUM(L17:L20)) | M21: =IF(COUNT(M17:M20)=0,"",SUM(M17:M20)) | N21: =IF(COUNT(N17:N20)=0,"",SUM(N17:N20)) | ... AP21: =IF(COUNT(AP17:AP20)=0,"",SUM(AP17:AP20)) | AQ21: =R21 | AR21: =AD21 | AS21: =AP21
A22: BS_EQ | B22: Equity | D22: + | E22: TB/Map | AQ22: =R22 | AR22: =AD22 | AS22: =AP22
A23: BS_TLE | B23: Total liabilities + equity | D23: + | E23: Formula | F23: Derived | G23: =IF(COUNT(G21:G22)=0,"",SUM(G21:G22)) | H23: =IF(COUNT(H21:H22)=0,"",SUM(H21:H22)) | I23: =IF(COUNT(I21:I22)=0,"",SUM(I21:I22)) | J23: =IF(COUNT(J21:J22)=0,"",SUM(J21:J22)) | K23: =IF(COUNT(K21:K22)=0,"",SUM(K21:K22)) | L23: =IF(COUNT(L21:L22)=0,"",SUM(L21:L22)) | M23: =IF(COUNT(M21:M22)=0,"",SUM(M21:M22)) | N23: =IF(COUNT(N21:N22)=0,"",SUM(N21:N22)) | ... AP23: =IF(COUNT(AP21:AP22)=0,"",SUM(AP21:AP22)) | AQ23: =R23 | AR23: =AD23 | AS23: =AP23
A27: BS_CHECKS
A28: Balance check (Assets - Liabilities & Equity) | G28: =IF(OR(G16="",G23=""),"",G16-G23) | H28: =IF(OR(H16="",H23=""),"",H16-H23) | I28: =IF(OR(I16="",I23=""),"",I16-I23) | J28: =IF(OR(J16="",J23=""),"",J16-J23) | K28: =IF(OR(K16="",K23=""),"",K16-K23) | L28: =IF(OR(L16="",L23=""),"",L16-L23) | M28: =IF(OR(M16="",M23=""),"",M16-M23) | N28: =IF(OR(N16="",N23=""),"",N16-N23) | ... AS28: =IF(OR(AS16="",AS23=""),"",AS16-AS23)

Sheet Entity 1 | CF
A1: Entity 1 CF
A2: Source: <document_source>
A7: Entity 1 CF
A8: LineKey | B8: $'000 | C8: TB Account No. | D8: Sign | E8: Source | F8: Comments | G8: ='Control | Setup'!A22 | H8: ='Control | Setup'!A23 | I8: ='Control | Setup'!A24 | J8: ='Control | Setup'!A25 | K8: ='Control | Setup'!A26 | L8: ='Control | Setup'!A27 | M8: ='Control | Setup'!A28 | N8: ='Control | Setup'!A29 | O8: ='Control | Setup'!A30 | P8: ='Control | Setup'!A31 | Q8: ='Control | Setup'!A32 | R8: ='Control | Setup'!A33 | S8: ='Control | Setup'!A34 | T8: ='Control | Setup'!A35 | U8: ='Control | Setup'!A36 | V8: ='Control | Setup'!A37 | W8: ='Control | Setup'!A38 | X8: ='Control | Setup'!A39 | Y8: ='Control | Setup'!A40 | Z8: ='Control | Setup'!A41 | AA8: ='Control | Setup'!A42 | AB8: ='Control | Setup'!A43 | AC8: ='Control | Setup'!A44 | AD8: ='Control | Setup'!A45 | AE8: ='Control | Setup'!A46 | AF8: ='Control | Setup'!A47 | AG8: ='Control | Setup'!A48 | AH8: ='Control | Setup'!A49 | AI8: ='Control | Setup'!A50 | AJ8: ='Control | Setup'!A51 | AK8: ='Control | Setup'!A52 | AL8: ='Control | Setup'!A53 | AM8: ='Control | Setup'!A54 | AN8: ='Control | Setup'!A55 | AO8: ='Control | Setup'!A56 | AP8: ='Control | Setup'!A57 | AQ8: FY-2 | AR8: FY-1 | AS8: TTM
A9: CF_EBITDA | B9: EBITDA | D9: + | E9: Link/Map | AQ9: =IF(COUNT(G9:R9)=0,"",SUM(G9:R9)) | AR9: =IF(COUNT(S9:AD9)=0,"",SUM(S9:AD9)) | AS9: =IF(COUNT(AE9:AP9)=0,"",SUM(AE9:AP9))
A10: CF_CHG_NWC | B10: Change in NWC | D10: + | E10: Link/Map | AQ10: =IF(COUNT(G10:R10)=0,"",SUM(G10:R10)) | AR10: =IF(COUNT(S10:AD10)=0,"",SUM(S10:AD10)) | AS10: =IF(COUNT(AE10:AP10)=0,"",SUM(AE10:AP10))
A11: CF_CAPEX | B11: Capex | D11: + | E11: Link/Map | AQ11: =IF(COUNT(G11:R11)=0,"",SUM(G11:R11)) | AR11: =IF(COUNT(S11:AD11)=0,"",SUM(S11:AD11)) | AS11: =IF(COUNT(AE11:AP11)=0,"",SUM(AE11:AP11))
A12: CF_OTHER | B12: Other | D12: + | E12: Link/Map | AQ12: =IF(COUNT(G12:R12)=0,"",SUM(G12:R12)) | AR12: =IF(COUNT(S12:AD12)=0,"",SUM(S12:AD12)) | AS12: =IF(COUNT(AE12:AP12)=0,"",SUM(AE12:AP12))
A13: CF_NET | B13: Net cash flow | D13: + | E13: Formula | F13: Derived | G13: =IF(COUNT(G9:G12)=0,"",SUM(G9:G12)) | H13: =IF(COUNT(H9:H12)=0,"",SUM(H9:H12)) | I13: =IF(COUNT(I9:I12)=0,"",SUM(I9:I12)) | J13: =IF(COUNT(J9:J12)=0,"",SUM(J9:J12)) | K13: =IF(COUNT(K9:K12)=0,"",SUM(K9:K12)) | L13: =IF(COUNT(L9:L12)=0,"",SUM(L9:L12)) | M13: =IF(COUNT(M9:M12)=0,"",SUM(M9:M12)) | N13: =IF(COUNT(N9:N12)=0,"",SUM(N9:N12)) | ... AP13: =IF(COUNT(AP9:AP12)=0,"",SUM(AP9:AP12)) | AQ13: =IF(COUNT(G13:R13)=0,"",SUM(G13:R13)) | AR13: =IF(COUNT(S13:AD13)=0,"",SUM(S13:AD13)) | AS13: =IF(COUNT(AE13:AP13)=0,"",SUM(AE13:AP13))
A27: CF_CHECKS
A28: Net cash tie-out | G28: =IF(G13="","",G13-SUM(G9:G12)) | H28: =IF(H13="","",H13-SUM(H9:H12)) | I28: =IF(I13="","",I13-SUM(I9:I12)) | J28: =IF(J13="","",J13-SUM(J9:J12)) | K28: =IF(K13="","",K13-SUM(K9:K12)) | L28: =IF(L13="","",L13-SUM(L9:L12)) | M28: =IF(M13="","",M13-SUM(M9:M12)) | N28: =IF(N13="","",N13-SUM(N9:N12)) | ... AS28: =IF(AS13="","",AS13-SUM(AS9:AS12))

Sheet QofE>>
A1: QofE>>
A4: =HYPERLINK("#'QofE | Summary'!A1","Go to QofE | Summary")
A5: =HYPERLINK("#'QofE | Detail'!A1","Go to QofE | Detail")

Sheet QofE | Summary
A1: QofE Summary
A2: Source: <document_source>
A7: QofE Summary
A8: LineKey | B8: $'000 | C8: TB Account No. | D8: Sign | E8: Source | F8: Comments | G8: FY-3 | H8: FY-2 | I8: FY-1 | J8: TTM
A9: Q_REV_REP | B9: Revenue - Reported | D9: + | E9: Input
A10: Q_REV_DD | B10: Revenue - DD Adj | D10: + | E10: Input
A11: Q_REV_PF | B11: Revenue - PF Adj | D11: + | E11: Input
A12: Q_REV_ADJ | B12: Revenue - Adjusted | D12: + | E12: Formula | F12: Derived | G12: =IF(COUNT(G9:G11)=0,"",SUM(G9:G11)) | H12: =IF(COUNT(H9:H11)=0,"",SUM(H9:H11)) | I12: =IF(COUNT(I9:I11)=0,"",SUM(I9:I11)) | J12: =IF(COUNT(J9:J11)=0,"",SUM(J9:J11))
A13: Q_EB_REP | B13: EBITDA - Reported | D13: + | E13: Input
A14: Q_EB_DD | B14: EBITDA - DD Adj | D14: + | E14: Input
A15: Q_EB_PF | B15: EBITDA - PF Adj | D15: + | E15: Input
A16: Q_EB_ADJ | B16: EBITDA - Adjusted | D16: + | E16: Formula | F16: Derived | G16: =IF(COUNT(G13:G15)=0,"",SUM(G13:G15)) | H16: =IF(COUNT(H13:H15)=0,"",SUM(H13:H15)) | I16: =IF(COUNT(I13:I15)=0,"",SUM(I13:I15)) | J16: =IF(COUNT(J13:J15)=0,"",SUM(J13:J15))
A17: Q_MARGIN | B17: EBITDA Margin % | D17: + | E17: Formula | F17: Derived | G17: =IF(OR(G12="",G16="",G12=0),"",G16/G12) | H17: =IF(OR(H12="",H16="",H12=0),"",H16/H12) | I17: =IF(OR(I12="",I16="",I12=0),"",I16/I12) | J17: =IF(OR(J12="",J16="",J12=0),"",J16/J12)
A19: QOFE_SUMMARY_CHECKS
A20: Revenue tie-out vs QofE Detail
A21: EBITDA tie-out vs QofE Detail

Sheet QofE | Detail
A1: QofE Detail
A2: Source: <document_source>
A7: QofE Detail
A8: LineKey | B8: $'000 | C8: TB Account No. | D8: Sign | E8: Source | F8: Comments | G8: ='Control | Setup'!A22 | H8: ='Control | Setup'!A23 | I8: ='Control | Setup'!A24 | J8: ='Control | Setup'!A25 | K8: ='Control | Setup'!A26 | L8: ='Control | Setup'!A27 | M8: ='Control | Setup'!A28 | N8: ='Control | Setup'!A29 | O8: ='Control | Setup'!A30 | P8: ='Control | Setup'!A31 | Q8: ='Control | Setup'!A32 | R8: ='Control | Setup'!A33 | S8: ='Control | Setup'!A34 | T8: ='Control | Setup'!A35 | U8: ='Control | Setup'!A36 | V8: ='Control | Setup'!A37 | W8: ='Control | Setup'!A38 | X8: ='Control | Setup'!A39 | Y8: ='Control | Setup'!A40 | Z8: ='Control | Setup'!A41 | AA8: ='Control | Setup'!A42 | AB8: ='Control | Setup'!A43 | AC8: ='Control | Setup'!A44 | AD8: ='Control | Setup'!A45 | AE8: ='Control | Setup'!A46 | AF8: ='Control | Setup'!A47 | AG8: ='Control | Setup'!A48 | AH8: ='Control | Setup'!A49 | AI8: ='Control | Setup'!A50 | AJ8: ='Control | Setup'!A51 | AK8: ='Control | Setup'!A52 | AL8: ='Control | Setup'!A53 | AM8: ='Control | Setup'!A54 | AN8: ='Control | Setup'!A55 | AO8: ='Control | Setup'!A56 | AP8: ='Control | Setup'!A57 | AQ8: FY-2 | AR8: FY-1 | AS8: TTM
A9: QD_REV | B9: Revenue | D9: + | E9: TB/Map | AQ9: =IF(COUNT(G9:R9)=0,"",SUM(G9:R9)) | AR9: =IF(COUNT(S9:AD9)=0,"",SUM(S9:AD9)) | AS9: =IF(COUNT(AE9:AP9)=0,"",SUM(AE9:AP9))
A10: QD_COGS | B10: Cost of goods sold | D10: + | E10: TB/Map | AQ10: =IF(COUNT(G10:R10)=0,"",SUM(G10:R10)) | AR10: =IF(COUNT(S10:AD10)=0,"",SUM(S10:AD10)) | AS10: =IF(COUNT(AE10:AP10)=0,"",SUM(AE10:AP10))
A11: QD_OPEX | B11: Operating expenses | D11: + | E11: TB/Map | AQ11: =IF(COUNT(G11:R11)=0,"",SUM(G11:R11)) | AR11: =IF(COUNT(S11:AD11)=0,"",SUM(S11:AD11)) | AS11: =IF(COUNT(AE11:AP11)=0,"",SUM(AE11:AP11))
A12: QD_EBITDA_REP | B12: EBITDA - Reported | D12: + | E12: Formula | F12: Derived | G12: =IF(COUNT(G9:G11)=0,"",G9+G10+G11) | H12: =IF(COUNT(H9:H11)=0,"",H9+H10+H11) | I12: =IF(COUNT(I9:I11)=0,"",I9+I10+I11) | J12: =IF(COUNT(J9:J11)=0,"",J9+J10+J11) | K12: =IF(COUNT(K9:K11)=0,"",K9+K10+K11) | L12: =IF(COUNT(L9:L11)=0,"",L9+L10+L11) | M12: =IF(COUNT(M9:M11)=0,"",M9+M10+M11) | N12: =IF(COUNT(N9:N11)=0,"",N9+N10+N11) | ... AP12: =IF(COUNT(AP9:AP11)=0,"",AP9+AP10+AP11) | AQ12: =IF(COUNT(G12:R12)=0,"",SUM(G12:R12)) | AR12: =IF(COUNT(S12:AD12)=0,"",SUM(S12:AD12)) | AS12: =IF(COUNT(AE12:AP12)=0,"",SUM(AE12:AP12))
A13: QD_DD | B13: DD adjustments | D13: + | E13: Manual | AQ13: =IF(COUNT(G13:R13)=0,"",SUM(G13:R13)) | AR13: =IF(COUNT(S13:AD13)=0,"",SUM(S13:AD13)) | AS13: =IF(COUNT(AE13:AP13)=0,"",SUM(AE13:AP13))
A14: QD_PF | B14: PF adjustments | D14: + | E14: Manual | AQ14: =IF(COUNT(G14:R14)=0,"",SUM(G14:R14)) | AR14: =IF(COUNT(S14:AD14)=0,"",SUM(S14:AD14)) | AS14: =IF(COUNT(AE14:AP14)=0,"",SUM(AE14:AP14))
A15: QD_EBITDA_ADJ | B15: EBITDA - Adjusted | D15: + | E15: Formula | F15: Derived | G15: =IF(COUNT(G12:G14)=0,"",G12+G13+G14) | H15: =IF(COUNT(H12:H14)=0,"",H12+H13+H14) | I15: =IF(COUNT(I12:I14)=0,"",I12+I13+I14) | J15: =IF(COUNT(J12:J14)=0,"",J12+J13+J14) | K15: =IF(COUNT(K12:K14)=0,"",K12+K13+K14) | L15: =IF(COUNT(L12:L14)=0,"",L12+L13+L14) | M15: =IF(COUNT(M12:M14)=0,"",M12+M13+M14) | N15: =IF(COUNT(N12:N14)=0,"",N12+N13+N14) | ... AP15: =IF(COUNT(AP12:AP14)=0,"",AP12+AP13+AP14) | AQ15: =IF(COUNT(G15:R15)=0,"",SUM(G15:R15)) | AR15: =IF(COUNT(S15:AD15)=0,"",SUM(S15:AD15)) | AS15: =IF(COUNT(AE15:AP15)=0,"",SUM(AE15:AP15))
A27: QOFE_DETAIL_CHECKS
A28: Adjusted EBITDA tie-out | G28: =IF(G15="","",G15-(G12+G13+G14)) | H28: =IF(H15="","",H15-(H12+H13+H14)) | I28: =IF(I15="","",I15-(I12+I13+I14)) | J28: =IF(J15="","",J15-(J12+J13+J14)) | K28: =IF(K15="","",K15-(K12+K13+K14)) | L28: =IF(L15="","",L15-(L12+L13+L14)) | M28: =IF(M15="","",M15-(M12+M13+M14)) | N28: =IF(N15="","",N15-(N12+N13+N14)) | ... AS28: =IF(AS15="","",AS15-(AS12+AS13+AS14))

Sheet NWC>>
A1: NWC>>
A4: =HYPERLINK("#'NWC | Summary'!A1","Go to NWC | Summary")
A5: =HYPERLINK("#'NWC | Detail'!A1","Go to NWC | Detail")
A6: =HYPERLINK("#'NWC | Days'!A1","Go to NWC | Days")
A7: =HYPERLINK("#'Stratified | BS'!A1","Go to Stratified | BS")
A8: =HYPERLINK("#'Net_debt'!A1","Go to Net_debt")

Sheet NWC | Summary
A1: NWC Summary
A2: Source: <document_source>
A7: NWC Summary
A8: LineKey | B8: $'000 | C8: TB Account No. | D8: Sign | E8: Source | F8: Comments | G8: FY-2 YE | H8: FY-1 YE | I8: Latest ME | J8: FY-2 Avg | K8: FY-1 Avg | L8: TTM Avg
A9: NWC_REP | B9: Reported NWC | D9: + | E9: Input
A10: NWC_DD | B10: DD Adjustment | D10: + | E10: Input
A11: NWC_PF | B11: PF Adjustment | D11: + | E11: Input
A12: NWC_ADJ | B12: Adjusted NWC | D12: + | E12: Formula | F12: Derived | G12: =IF(COUNT(G9:G11)=0,"",SUM(G9:G11)) | H12: =IF(COUNT(H9:H11)=0,"",SUM(H9:H11)) | I12: =IF(COUNT(I9:I11)=0,"",SUM(I9:I11)) | J12: =IF(COUNT(J9:J11)=0,"",SUM(J9:J11)) | K12: =IF(COUNT(K9:K11)=0,"",SUM(K9:K11)) | L12: =IF(COUNT(L9:L11)=0,"",SUM(L9:L11))
A13: NWC_SALES | B13: Sales (TTM) | D13: + | E13: Input
A14: NWC_PCT | B14: NWC % Sales | D14: + | E14: Formula | F14: Derived | G14: =IF(OR(G12="",G13="",G13=0),"",G12/G13) | H14: =IF(OR(H12="",H13="",H13=0),"",H12/H13) | I14: =IF(OR(I12="",I13="",I13=0),"",I12/I13) | J14: =IF(OR(J12="",J13="",J13=0),"",J12/J13) | K14: =IF(OR(K12="",K13="",K13=0),"",K12/K13) | L14: =IF(OR(L12="",L13="",L13=0),"",L12/L13)
A16: NWC_SUMMARY_CHECKS
A17: Adjusted NWC tie-out vs NWC Detail

Sheet NWC | Detail
A1: NWC Detail
A2: Source: <document_source>
A7: NWC Detail
A8: LineKey | B8: $'000 | C8: TB Account No. | D8: Sign | E8: Source | F8: Comments | G8: ='Control | Setup'!A22 | H8: ='Control | Setup'!A23 | I8: ='Control | Setup'!A24 | J8: ='Control | Setup'!A25 | K8: ='Control | Setup'!A26 | L8: ='Control | Setup'!A27 | M8: ='Control | Setup'!A28 | N8: ='Control | Setup'!A29 | O8: ='Control | Setup'!A30 | P8: ='Control | Setup'!A31 | Q8: ='Control | Setup'!A32 | R8: ='Control | Setup'!A33 | S8: ='Control | Setup'!A34 | T8: ='Control | Setup'!A35 | U8: ='Control | Setup'!A36 | V8: ='Control | Setup'!A37 | W8: ='Control | Setup'!A38 | X8: ='Control | Setup'!A39 | Y8: ='Control | Setup'!A40 | Z8: ='Control | Setup'!A41 | AA8: ='Control | Setup'!A42 | AB8: ='Control | Setup'!A43 | AC8: ='Control | Setup'!A44 | AD8: ='Control | Setup'!A45 | AE8: ='Control | Setup'!A46 | AF8: ='Control | Setup'!A47 | AG8: ='Control | Setup'!A48 | AH8: ='Control | Setup'!A49 | AI8: ='Control | Setup'!A50 | AJ8: ='Control | Setup'!A51 | AK8: ='Control | Setup'!A52 | AL8: ='Control | Setup'!A53 | AM8: ='Control | Setup'!A54 | AN8: ='Control | Setup'!A55 | AO8: ='Control | Setup'!A56 | AP8: ='Control | Setup'!A57 | AQ8: FY-2 | AR8: FY-1 | AS8: TTM
A9: NWC_AR | B9: Accounts receivable | D9: + | E9: Class map | AQ9: =IF(COUNT(G9:R9)=0,"",SUM(G9:R9)) | AR9: =IF(COUNT(S9:AD9)=0,"",SUM(S9:AD9)) | AS9: =IF(COUNT(AE9:AP9)=0,"",SUM(AE9:AP9))
A10: NWC_INV | B10: Inventory | D10: + | E10: Class map | AQ10: =IF(COUNT(G10:R10)=0,"",SUM(G10:R10)) | AR10: =IF(COUNT(S10:AD10)=0,"",SUM(S10:AD10)) | AS10: =IF(COUNT(AE10:AP10)=0,"",SUM(AE10:AP10))
A11: NWC_AP | B11: Accounts payable | D11: + | E11: Class map | AQ11: =IF(COUNT(G11:R11)=0,"",SUM(G11:R11)) | AR11: =IF(COUNT(S11:AD11)=0,"",SUM(S11:AD11)) | AS11: =IF(COUNT(AE11:AP11)=0,"",SUM(AE11:AP11))
A12: NWC_ACCR | B12: Accruals | D12: + | E12: Class map | AQ12: =IF(COUNT(G12:R12)=0,"",SUM(G12:R12)) | AR12: =IF(COUNT(S12:AD12)=0,"",SUM(S12:AD12)) | AS12: =IF(COUNT(AE12:AP12)=0,"",SUM(AE12:AP12))
A13: NWC_OTH | B13: Other | D13: + | E13: Class map | AQ13: =IF(COUNT(G13:R13)=0,"",SUM(G13:R13)) | AR13: =IF(COUNT(S13:AD13)=0,"",SUM(S13:AD13)) | AS13: =IF(COUNT(AE13:AP13)=0,"",SUM(AE13:AP13))
A14: NWC_TOTAL | B14: Total NWC | D14: + | E14: Formula | F14: Derived | G14: =IF(COUNT(G9:G13)=0,"",SUM(G9:G13)) | H14: =IF(COUNT(H9:H13)=0,"",SUM(H9:H13)) | I14: =IF(COUNT(I9:I13)=0,"",SUM(I9:I13)) | J14: =IF(COUNT(J9:J13)=0,"",SUM(J9:J13)) | K14: =IF(COUNT(K9:K13)=0,"",SUM(K9:K13)) | L14: =IF(COUNT(L9:L13)=0,"",SUM(L9:L13)) | M14: =IF(COUNT(M9:M13)=0,"",SUM(M9:M13)) | N14: =IF(COUNT(N9:N13)=0,"",SUM(N9:N13)) | ... AP14: =IF(COUNT(AP9:AP13)=0,"",SUM(AP9:AP13)) | AQ14: =IF(COUNT(G14:R14)=0,"",SUM(G14:R14)) | AR14: =IF(COUNT(S14:AD14)=0,"",SUM(S14:AD14)) | AS14: =IF(COUNT(AE14:AP14)=0,"",SUM(AE14:AP14))
A27: NWC_DETAIL_CHECKS
A28: NWC total tie-out vs Stratified BS

Sheet NWC | Days
A1: NWC Days
A2: Source: <document_source>
A7: NWC Days
A8: Metric | B8: Jan | C8: Feb | D8: Mar | E8: Apr | F8: May | G8: Jun | H8: Jul | I8: Aug | J8: Sep | K8: Oct | L8: Nov | M8: Dec | N8: FY Avg | O8: FY Min | P8: FY Max
A9: DSO
A10: DPO
A11: DIO
A12: CCC
A27: NWC_DAYS_CHECKS
A28: Days metrics reasonableness review

Sheet Stratified | BS
A1: Stratified BS
A2: Source: <document_source>
A7: Stratified BS
